Workbook

Sheet Bug Tracker - 85
A1: Bug ID | B1: Original Defect ID | C1: Test Case ID | D1: Level | E1: Module | F1: Submodule | G1: Scenario | H1: Test Type | I1: Role | J1: Priority | K1: Release Gate | L1: Original Status | M1: Bug Type | N1: Severity | O1: Bug Status | P1: Developer Name | Q1: Developer Rework Date | R1: Opened Date | S1: Target Fix Date | T1: QA Retest Date | U1: Retest Result | V1: Final Status | W1: Age Days | X1: Environment | Y1: Build | Z1: Fix Build | AA1: Tester | AB1: Preconditions | AC1: Test Data | AD1: Steps | AE1: Expected Result | AF1: Actual Result | AG1: Reason / Root Cause | AH1: Developer Rework Required | AI1: Fix Notes | AJ1: Evidence Link | AK1: Comments
A2: BUG-001 | B2: DL1001 | C2: L1-001 | D2: Level 1 | E2: Platform | G2: Provision a lab tenant | H2: Smoke | I2: Developer Admin | J2: High | K2: Yes | L2: Failed | M2: Functional Bug | N2: High | O2: Open | P2: Unassigned | R2: 46262 | U2: Pending | V2: Open | W2: =IF(R2="","",TODAY()-R2) -> 21 | X2: UAT | AA2: Premothan V | AB2: Required master data and user exist. | AC2: Use dedicated non-production test data. | AD2: 1. Sign in as Developer Admin. 2. Create a lab with an active plan and required modules. 3. Save or submit. 4. Refresh or reopen the record. 5. Compare the result with the pass condition. | AE2: The tenant is created, isolated and can open its login page. | AF2: Lab created successfully. But facing two bugs, and the concept needs to be altered. | AG2: Failed result requires rework: Lab created successfully. But facing two bugs, and the concept needs to be altered. | AH2: Fix Platform workflow for "Provision a lab tenant" so actual behavior matches expected result: The tenant is created, isolated and can open its login page. | AK2: Please refer to the evidence link
A3: BUG-002 | B3: DL1004 | C3: L1-004 | D3: Level 1 | E3: Inventory | G3: Load opening stock | H3: Smoke | I3: Inventory Manager | J3: High | K3: Yes | L3: Failed | M3: Functional Bug | N3: Low | O3: Open | P3: Unassigned | R3: 46268 | U3: Pending | V3: Open | W3: =IF(R3="","",TODAY()-R3) -> 15 | X3: UAT | AA3: Premothan V | AB3: Required master data and user exist. | AC3: Use dedicated non-production test data. | AD3: 1. Sign in as Inventory Manager. 2. Create required inventory masters and load stock with batch and expiry. 3. Save or submit. 4. Refresh or reopen the record. 5. Compare the result with the pass condition. | AE3: On-hand stock, batch, UOM and expiry are correct. | AF3: Created everything. But the name field length must be extended | AG3: Validation/UI rule issue: field constraints or required-field behavior do not match expected workflow. | AH3: Fix Inventory workflow for "Load opening stock" so actual behavior matches expected result: On-hand stock, batch, UOM and expiry are correct. | AK3: Need to retest
A4: BUG-003 | B4: DL1010 | C4: L1-010 | D4: Level 1 | E4: Samples | G4: Print or open sample barcode | H4: Smoke | I4: Phlebotomist | J4: High | K4: Yes | L4: Failed | M4: Functional Bug | N4: Medium | O4: Open | P4: Unassigned | U4: Not Required | V4: Open | W4: =IF(R4="","",TODAY()-R4) | X4: QA | AA4: Stephen | AB4: Required master data and user exist. | AC4: Use dedicated non-production test data. | AD4: 1. Sign in as Phlebotomist. 2. Open the generated sample and barcode. 3. Save or submit. 4. Refresh or reopen the record. 5. Compare the result with the pass condition. | AE4: Sample ID, barcode, patient, bill and required sample type match. | AF4: Can't create an appropriate role. | AG4: Access/RBAC setup issue: required role or permission does not allow the testcase workflow to complete. | AH4: Fix Samples workflow for "Print or open sample barcode" so actual behavior matches expected result: Sample ID, barcode, patient, bill and required sample type match.
A5: BUG-004 | B5: DL1011 | C5: L1-011 | D5: Level 1 | E5: Samples | G5: Collect the sample | H5: Smoke | I5: Phlebotomist | J5: High | K5: Yes | L5: Failed | M5: Functional Bug | N5: Medium | O5: Open | P5: Unassigned | U5: Not Required | V5: Open | W5: =IF(R5="","",TODAY()-R5) | X5: QA | AA5: Stephen | AB5: Required master data and user exist. | AC5: Use dedicated non-production test data. | AD5: 1. Sign in as Phlebotomist. 2. Verify two patient identifiers, record collection/received details and mark Collected. 3. Save or submit. 4. Refresh or reopen the record. 5. Compare the result with the pass condition. | AE5: Collection time, collector and custody event are saved. | AF5: Can't create an appropriate role. | AG5: Access/RBAC setup issue: required role or permission does not allow the testcase workflow to complete. | AH5: Fix Samples workflow for "Collect the sample" so actual behavior matches expected result: Collection time, collector and custody event are saved.
A6: BUG-005 | B6: DL1012 | C6: L1-012 | D6: Level 1 | E6: Samples | G6: Move sample to processing | H6: Smoke | I6: Lab Technician | J6: High | K6: Yes | L6: Failed | M6: Functional Bug | N6: High | O6: Open | P6: Unassigned | R6: 46267 | U6: Not Required | V6: Open | W6: =IF(R6="","",TODAY()-R6) -> 16 | X6: QA | AA6: Rishidharshini | AB6: Required master data and user exist. | AC6: Use dedicated non-production test data. | AD6: 1. Sign in as Lab Technician. 2. Open the collected sample and start processing. 3. Save or submit. 4. Refresh or reopen the record. 5. Compare the result with the pass condition. | AE6: Sample and bill-item statuses move forward in the correct order. | AF6: The sample is not coming to processing | AG6: Failed result requires rework: The sample is not coming to processing | AH6: Fix Samples workflow for "Move sample to processing" so actual behavior matches expected result: Sample and bill-item statuses move forward in the correct order. | AJ6: Defect SS
A7: BUG-006 | B7: DL1013 | C7: L1-013 | D7: Level 1 | E7: Inventory | G7: Reserve or monitor test inventory | H7: Smoke | I7: Lab Technician | J7: High | K7: Yes | L7: Failed | M7: Functional Bug | N7: High | O7: Open | P7: Unassigned | R7: 46267 | U7: Not Required | V7: Open | W7: =IF(R7="","",TODAY()-R7) -> 16 | X7: QA | AA7: Rishidharshini | AC7: Use dedicated non-production test data. | AD7: 1. Sign in as Lab Technician. 2. Check required item availability during sample processing. 3. Save or submit. 4. Refresh or reopen the record. 5. Compare the result with the pass condition. | AE7: Reserved/on-hand stock and warnings follow the implemented rule. | AF7: The Inventory Item can be submitted even if there is no stock and also when it begin to process, added inventory item is not available | AG7: Inventory workflow issue: stock, UOM, expiry, or master data behavior does not meet expected result. | AH7: Fix Inventory workflow for "Reserve or monitor test inventory" so actual behavior matches expected result: Reserved/on-hand stock and warnings follow the implemented rule. | AJ7: Defect SS
A8: BUG-007 | B8: DL1018 | C8: L1-018 | D8: Level 1 | E8: Notifications | G8: Check report release notification | H8: Smoke | I8: Lab Manager | J8: High | K8: Yes | L8: Failed | M8: Functional Bug | N8: High | O8: Open | P8: Unassigned | R8: 46268 | U8: Not Required | V8: Open | W8: =IF(R8="","",TODAY()-R8) -> 15 | X8: QA | AA8: Rishidharshini | AB8: Required master data and user exist. | AC8: Use dedicated non-production test data. | AD8: 1. Sign in as Lab Manager. 2. Refresh notifications after report release. 3. Save or submit. 4. Refresh or reopen the record. 5. Compare the result with the pass condition. | AE8: Authorised users receive the correct report-release notification where implemented. | AF8: Notification not received when report released | AG8: Output/reporting issue: generated document, barcode, print, or download behavior needs correction. | AH8: Fix Notifications workflow for "Check report release notification" so actual behavior matches expected result: Authorised users receive the correct report-release notification where implemented. | AJ8: Defect SS
A9: BUG-008 | B9: DL2047 | C9: L1-019 | D9: Level 1 | E9: Doctor Portal | G9: View the referred patient's report | H9: Smoke | I9: Doctor Regular | J9: High | K9: Yes | L9: Failed | M9: Functional Bug | N9: High | O9: Open | P9: Unassigned | R9: 46268 | U9: Not Required | V9: Open | W9: =IF(R9="","",TODAY()-R9) -> 15 | X9: UAT | AB9: Required master data and user exist. | AC9: Use dedicated non-production test data. | AD9: 1. Sign in as Doctor Regular. 2. Sign in as the linked doctor and open the referred patient. 3. Save or submit. 4. Refresh or reopen the record. 5. Compare the result with the pass condition. | AE9: Only owned referrals and Released reports are visible. | AF9: The doctor was created successfully with the commission percentage given, but that is not reflected in the Doctor details UI. Also, when I tried to log in as a doctor, the message showed that access was denied. So, I have tried to provide access for a doctor, but I am unable to save the changes. Also, please remove doctor roles from the Roles and Permissions area. | AG9: Access/RBAC setup issue: required role or permission does not allow the testcase workflow to complete. | AH9: Fix Doctor Portal workflow for "View the referred patient's report" so actual behavior matches expected result: Only owned referrals and Released reports are visible. | AK9: Need to fix the bug
A10: BUG-009 | B10: DL2050 | C10: L1-022 | D10: Level 1 | E10: Billing | G10: Complete payment | H10: Smoke | I10: Billing Cashier | J10: Critical | K10: Yes | L10: Failed | M10: Functional Bug | N10: Medium | O10: Open | P10: Unassigned | U10: Not Required | V10: Open | W10: =IF(R10="","",TODAY()-R10) | X10: UAT | AA10: Stephen | AB10: Required master data and user exist. | AC10: Use dedicated non-production test data. | AD10: 1. Sign in as Billing Cashier. 2. Pay the remaining balance and issue the final receipt. 3. Save or submit. 4. Refresh or reopen the record. 5. Compare the result with the pass condition. | AE10: Bill status becomes Paid and balance becomes zero. | AF10: The total bill amount has been paid. But the pending amount is still showing in the view bill. | AG10: Billing/accounts workflow issue: financial transaction or document flow needs developer rework. | AH10: Fix Billing workflow for "Complete payment" so actual behavior matches expected result: Bill status becomes Paid and balance becomes zero.
A11: BUG-010 | B11: DL2158 | C11: L2-006 | D11: Level 2 | E11: Authentication & Session | G11: Reset token reuse | H11: Security | I11: Tenant User | J11: High | K11: No | L11: Failed | M11: Functional Bug | N11: High | O11: Open | P11: Unassigned | R11: 46269 | U11: Not Required | V11: Open | W11: =IF(R11="","",TODAY()-R11) -> 14 | X11: QA | AA11: Rishidharshini | AB11: Required master data and user exist. | AC11: Use dedicated non-production test data. | AD11: 1. Sign in as Tenant User. 2. Use a reset credential twice. 3. Save or submit. 4. Refresh or reopen the record. 5. Compare the result with the pass condition. | AE11: The second use is denied. | AF11: The second use is not denied. The current password and the new password are the same. | AG11: Failed result requires rework: The second use is not denied. The current password and the new password are the same. | AH11: Fix Authentication & Session workflow for "Reset token reuse" so actual behavior matches expected result: The second use is denied. | AJ11: Defect SS
A12: BUG-011 | B12: DL2161 | C12: L2-009 | D12: Level 2 | E12: Authentication & Session | G12: Session expiry | H12: Functional | I12: Tenant User | J12: Medium | K12: No | L12: Failed | M12: Functional Bug | N12: Medium | O12: Open | P12: Unassigned | R12: 46269 | U12: Not Required | V12: Open | W12: =IF(R12="","",TODAY()-R12) -> 14 | X12: QA | AA12: Rishidharshini | AB12: Required master data and user exist. | AC12: Use dedicated non-production test data. | AD12: 1. Sign in as Tenant User. 2. Use an expired session on UI and API. 3. Save or submit. 4. Refresh or reopen the record. 5. Compare the result with the pass condition. | AE12: The user is asked to sign in again. | AF12: The user is not asked to sign in again. | AG12: Inventory workflow issue: stock, UOM, expiry, or master data behavior does not meet expected result. | AH12: Fix Authentication & Session workflow for "Session expiry" so actual behavior matches expected result: The user is asked to sign in again. | AJ12: Defect SS
A13: BUG-012 | B13: DL2013 | C13: L2-013 | D13: Level 2 | E13: RBAC & Settings | G13: Dangerous permission grant | H13: Functional | J13: Critical | K13: Yes | L13: N/A | M13: N/A Scope Review | N13: Low | O13: Needs Review | P13: Varshini | Q13: 18/09/2026 | R13: 46269 | U13: Pending | V13: Scope Review Pending | W13: =IF(R13="","",TODAY()-R13) -> 14 | X13: UAT | AA13: Abinesh | AB13: Required master data and user exist. | AC13: Use dedicated non-production test data. | AD13: 1. Sign in as Admin. 2. Grant refund, release or user-management permission. 3. Save or submit. 4. Refresh or reopen the record. 5. Compare the result with the pass condition. | AE13: The grant follows the approved control and is auditable. | AG13: N/A case requires QA/Product confirmation: mark as valid non-applicable, deferred scope, or convert to executable test. | AH13: Review with QA/Product, document N/A justification, and update testcase status or scope decision.
A14: BUG-013 | B14: DL2166 | C14: L2-014 | D14: Level 2 | E14: RBAC & Settings | G14: Assigned role deletion | H14: Functional | I14: Admin | J14: Medium | K14: No | L14: Failed | M14: Functional Bug | N14: High | O14: Open | P14: Unassigned | R14: 46268 | U14: Not Required | V14: Open | W14: =IF(R14="","",TODAY()-R14) -> 15 | X14: UAT | AA14: Abinesh | AB14: Required master data and user exist. | AC14: Use dedicated non-production test data. | AD14: 1. Sign in as Admin. 2. Try to delete a role assigned to a user. 3. Save or submit. 4. Refresh or reopen the record. 5. Compare the result with the pass condition. | AE14: Deletion is blocked. | AF14: The Lab Manager role was deleted even though it was already assigned to another user. After deletion, the system automatically assigned the first available role to the affected user. The user can then access the system based on the permissions of the newly assigned role. | AG14: Access/RBAC setup issue: required role or permission does not allow the testcase workflow to complete. | AH14: Fix RBAC & Settings workflow for "Assigned role deletion" so actual behavior matches expected result: Deletion is blocked. | AJ14: Defect SS
A15: BUG-014 | B15: DL2017 | C15: L2-017 | D15: Level 2 | E15: RBAC & Settings | G15: Disabled module API | H15: Functional | I15: Admin | J15: Medium | K15: No | L15: N/A | M15: N/A Scope Review | N15: Low | O15: Needs Review | P15: Kavin | Q15: 18/09/2026 | R15: 46268 | U15: Pending | V15: Scope Review Pending | W15: =IF(R15="","",TODAY()-R15) -> 15 | X15: UAT | AA15: Abinesh | AB15: Required master data and user exist. | AC15: Use dedicated non-production test data. | AD15: 1. Sign in as Admin. 2. Call the disabled module API directly. 3. Save or submit. 4. Refresh or reopen the record. 5. Compare the result with the pass condition. | AE15: The server denies the action. | AG15: N/A case requires QA/Product confirmation: mark as valid non-applicable, deferred scope, or convert to executable test. | AH15: Review with QA/Product, document N/A justification, and update testcase status or scope decision.
A16: BUG-015 | B16: DL2018 | C16: L2-018 | D16: Level 2 | E16: RBAC & Settings | G16: Technician collection denial | H16: Functional | I16: Admin | J16: Medium | K16: No | L16: Failed | M16: Functional Bug | N16: Medium | O16: Open | P16: Unassigned | R16: 46268 | U16: Not Required | V16: Open | W16: =IF(R16="","",TODAY()-R16) -> 15 | X16: UAT | AA16: Abinesh | AB16: Required master data and user exist. | AC16: Use dedicated non-production test data. | AD16: 1. Sign in as Admin. 2. Use Lab Technician to collect a sample. 3. Save or submit. 4. Refresh or reopen the record. 5. Compare the result with the pass condition. | AE16: The default role is denied. | AF16: The system should display a confirmation message when the Collect Sample permission is assigned to the Lab Technician role. | AG16: Access/RBAC setup issue: required role or permission does not allow the testcase workflow to complete. | AH16: Fix RBAC & Settings workflow for "Technician collection denial" so actual behavior matches expected result: The default role is denied. | AJ16: Defect SS
A17: BUG-016 | B17: DL2019 | C17: L2-019 | D17: Level 2 | E17: RBAC & Settings | G17: Technician release denial | H17: Functional | I17: Admin | J17: Medium | K17: No | L17: Failed | M17: Functional Bug | N17: Medium | O17: Open | P17: Unassigned | R17: 46268 | U17: Not Required | V17: Open | W17: =IF(R17="","",TODAY()-R17) -> 15 | X17: UAT | AA17: Abinesh | AB17: Required master data and user exist. | AC17: Use dedicated non-production test data. | AD17: 1. Sign in as Admin. 2. Use Lab Technician to release a report. 3. Save or submit. 4. Refresh or reopen the record. 5. Compare the result with the pass condition. | AE17: The default role is denied. | AF17: The system should display a confirmation message when the release a report permission is assigned to the Lab Technician role. | AG17: Access/RBAC setup issue: required role or permission does not allow the testcase workflow to complete. | AH17: Fix RBAC & Settings workflow for "Technician release denial" so actual behavior matches expected result: The default role is denied. | AJ17: Defect SS
A18: BUG-017 | B18: DL2021 | C18: L2-021 | D18: Level 2 | E18: RBAC & Settings | G18: Role change audit | H18: Functional | I18: Admin | J18: High | K18: No | L18: Failed | M18: Functional Bug | N18: High | O18: Open | P18: Unassigned | R18: 46268 | U18: Not Required | V18: Open | W18: =IF(R18="","",TODAY()-R18) -> 15 | X18: UAT | AA18: Abinesh | AB18: Required master data and user exist. | AC18: User : Abinesh Role : Account Manager Access Removed: Test, Inventory , Users | AD18: 1. Sign in as Admin. 2. Create and update a role. 3. Save or submit. 4. Refresh or reopen the record. 5. Compare the result with the pass condition. | AE18: Actor, old/new permissions and time are auditable. | AF18: Some permissions were removed from the Account Manager role, but the permission changes were not recorded in the Audit Log. The transaction details are missing from the audit records. | AG18: Access/RBAC setup issue: required role or permission does not allow the testcase workflow to complete. | AH18: Fix RBAC & Settings workflow for "Role change audit" so actual behavior matches expected result: Actor, old/new permissions and time are auditable. | AJ18: Defect SS
A19: BUG-018 | B19: DL2021 | C19: L2-022 | D19: Level 2 | E19: RBAC & Settings | G19: Inactive role | H19: Functional | I19: Admin | J19: Medium | K19: No | L19: Failed | M19: Functional Bug | N19: Medium | O19: Open | P19: Unassigned | R19: 46268 | U19: Not Required | V19: Open | W19: =IF(R19="","",TODAY()-R19) -> 15 | X19: UAT | AA19: Abinesh | AB19: Required master data and user exist. | AC19: Use dedicated non-production test data. | AD19: 1. Sign in as Admin. 2. Deactivate a role and try to use it. 3. Save or submit. 4. Refresh or reopen the record. 5. Compare the result with the pass condition. | AE19: The role cannot grant access. | AF19: The Active/Deactivate option is not available in the Role Assignment module, so the role assignment cannot be deactivated. | AG19: Access/RBAC setup issue: required role or permission does not allow the testcase workflow to complete. | AH19: Fix RBAC & Settings workflow for "Inactive role" so actual behavior matches expected result: The role cannot grant access. | AJ19: Defect SS | AK19: The Active/Deactivate option is missing from the Role Assignment module. As a result, the Admin cannot deactivate a user's role assignment as required by the test scenario.
A20: BUG-019 | B20: DL2029 | C20: L2-029 | D20: Level 2 | E20: Patients & Visits | G20: Edit patient | H20: Functional | I20: Front Desk Receptionist | J20: Medium | K20: No | L20: Failed | M20: Functional Bug | N20: Medium | O20: Open | P20: Unassigned | U20: Not Required | V20: Open | W20: =IF(R20="","",TODAY()-R20) | X20: UAT | AA20: Stephen | AB20: Required master data and user exist. | AC20: Use dedicated non-production test data. | AD20: 1. Sign in as Front Desk Receptionist. 2. Change allowed demographics and refresh. 3. Save or submit. 4. Refresh or reopen the record. 5. Compare the result with the pass condition. | AE20: Changes persist and linked records remain intact. | AF20: The patient information details have been changed, but cant working update profile option. | AG20: Failed result requires rework: The patient information details have been changed, but cant working update profile option. | AH20: Fix Patients & Visits workflow for "Edit patient" so actual behavior matches expected result: Changes persist and linked records remain intact.
A21: BUG-020 | B21: DL2032 | C21: L2-032 | D21: Level 2 | E21: Patients & Visits | G21: Soft delete and restore | H21: Functional | I21: Front Desk Receptionist | J21: Medium | K21: No | L21: Failed | M21: Functional Bug | N21: Medium | O21: Open | P21: Unassigned | U21: Not Required | V21: Open | W21: =IF(R21="","",TODAY()-R21) | X21: UAT | AA21: Stephen | AB21: Required master data and user exist. | AC21: Use dedicated non-production test data. | AD21: 1. Sign in as Front Desk Receptionist. 2. Delete and restore a patient. 3. Save or submit. 4. Refresh or reopen the record. 5. Compare the result with the pass condition. | AE21: History and links are preserved. | AF21: There are no patient restore options. | AG21: Failed result requires rework: There are no patient restore options. | AH21: Fix Patients & Visits workflow for "Soft delete and restore" so actual behavior matches expected result: History and links are preserved.
A22: BUG-021 | B22: DL2033 | C22: L2-033 | D22: Level 2 | E22: Patients & Visits | G22: Patient edit audit | H22: Functional | I22: Front Desk Receptionist | J22: Medium | K22: No | L22: Failed | M22: Functional Bug | N22: Medium | O22: Open | P22: Unassigned | U22: Not Required | V22: Open | W22: =IF(R22="","",TODAY()-R22) | X22: UAT | AA22: Stephen | AB22: Required master data and user exist. | AC22: Use dedicated non-production test data. | AD22: 1. Sign in as Front Desk Receptionist. 2. Change identity-sensitive fields. 3. Save or submit. 4. Refresh or reopen the record. 5. Compare the result with the pass condition. | AE22: Old/new values, actor and time are auditable. | AF22: The patient information details have been changed, but cant working update profile option. | AG22: Failed result requires rework: The patient information details have been changed, but cant working update profile option. | AH22: Fix Patients & Visits workflow for "Patient edit audit" so actual behavior matches expected result: Old/new values, actor and time are auditable.
A23: BUG-022 | B23: DL2036 | C23: L2-036 | D23: Level 2 | E23: Doctors & Commission | G23: Duplicate email | H23: Functional | I23: Admin | J23: Medium | K23: No | L23: Failed | M23: Functional Bug | N23: High | O23: Open | P23: Unassigned | R23: 46268 | U23: Not Required | V23: Open | W23: =IF(R23="","",TODAY()-R23) -> 15 | X23: UAT | AA23: Abinesh | AB23: Required master data and user exist. | AC23: Use dedicated non-production test data. | AD23: 1. Sign in as Admin. 2. Create two doctors with the same email. 3. Save or submit. 4. Refresh or reopen the record. 5. Compare the result with the pass condition. | AE23: Duplicate doctor/portal identity is blocked. | AF23: The system allows two doctors to be created with the same email address. No duplicate email validation message is displayed, and the second doctor record is saved successfully. | AG23: Validation/UI rule issue: field constraints or required-field behavior do not match expected workflow. | AH23: Fix Doctors & Commission workflow for "Duplicate email" so actual behavior matches expected result: Duplicate doctor/portal identity is blocked. | AJ23: Defect SS
A24: BUG-023 | B24: DL2039 | C24: L2-039 | D24: Level 2 | E24: Doctors & Commission | G24: Resend invitation | H24: Functional | I24: Admin | J24: Medium | K24: No | L24: Failed | M24: Functional Bug | N24: Medium | O24: Open | P24: Unassigned | R24: 46268 | U24: Not Required | V24: Open | W24: =IF(R24="","",TODAY()-R24) -> 15 | X24: UAT | AA24: Abinesh | AB24: Required master data and user exist. | AC24: Use dedicated non-production test data. | AD24: 1. Sign in as Admin. 2. Resend and try old and new OTPs. 3. Save or submit. 4. Refresh or reopen the record. 5. Compare the result with the pass condition. | AE24: Only the latest OTP works. | AF24: After the doctor successfully submits the OTP and logs in, resending the invitation OTP displays the message “This portal already has an active account.” | AG24: Portal/authentication workflow issue: login, activation, access, or visibility needs correction. | AH24: Fix Doctors & Commission workflow for "Resend invitation" so actual behavior matches expected result: Only the latest OTP works. | AJ24: Defect SS
A25: BUG-024 | B25: DL2040 | C25: L2-040 | D25: Level 2 | E25: Doctors & Commission | G25: Inactive doctor billing | H25: Functional | I25: Admin | J25: Medium | K25: No | L25: Failed | M25: Functional Bug | N25: Low | O25: Open | P25: Unassigned | R25: 46268 | U25: Not Required | V25: Open | W25: =IF(R25="","",TODAY()-R25) -> 15 | X25: UAT | AA25: Abinesh | AB25: Required master data and user exist. | AC25: Use dedicated non-production test data. | AD25: 1. Sign in as Admin. 2. Select an inactive referral doctor. 3. Save or submit. 4. Refresh or reopen the record. 5. Compare the result with the pass condition. | AE25: New billing is blocked. | AF25: When registering a patient, the inactive doctor does not appear in the Referral Code (LOV). When an existing patient is updated from “Doctor Referral = No” to “Yes”, the selected referral doctor is not updated in the patient record. | AG25: Billing/accounts workflow issue: financial transaction or document flow needs developer rework. | AH25: Fix Doctors & Commission workflow for "Inactive doctor billing" so actual behavior matches expected result: New billing is blocked. | AJ25: Defect SS | AK25: This scenario has already been tested by Stephen under test case DL-20029, and the appropriate screenshot has been added to the document as evidence.
A26: BUG-025 | B26: DL2043 | C26: L2-043 | D26: Level 2 | E26: Doctors & Commission | G26: Commission eligibility | H26: Functional | I26: Admin | J26: Medium | K26: No | L26: N/A | M26: N/A Scope Review | N26: Low | O26: Needs Review | P26: Unassigned | R26: 46268 | U26: Not Required | V26: Scope Review Pending | W26: =IF(R26="","",TODAY()-R26) -> 15 | X26: UAT | AA26: Abinesh | AB26: Required master data and user exist. | AC26: Use dedicated non-production test data. | AD26: 1. Sign in as Admin. 2. Compare unpaid, partial and paid referrals. 3. Save or submit. 4. Refresh or reopen the record. 5. Compare the result with the pass condition. | AE26: Estimated and earned commission follow policy. | AG26: N/A case requires QA/Product confirmation: mark as valid non-applicable, deferred scope, or convert to executable test. | AH26: Review with QA/Product, document N/A justification, and update testcase status or scope decision.
A27: BUG-026 | B27: DL2044 | C27: L2-044 | D27: Level 2 | E27: Doctors & Commission | G27: Payout approval | H27: Functional | I27: Admin | J27: High | K27: No | L27: Failed | M27: Functional Bug | N27: High | O27: Open | P27: Unassigned | R27: 46268 | U27: Not Required | V27: Open | W27: =IF(R27="","",TODAY()-R27) -> 15 | X27: UAT | AA27: Abinesh | AB27: Required master data and user exist. | AC27: Use dedicated non-production test data. | AD27: 1. Sign in as Admin. 2. Create and release a payout. 3. Save or submit. 4. Refresh or reopen the record. 5. Compare the result with the pass condition. | AE27: Only authorized staff can approve and the action is auditable. | AF27: The payout was released successfully, but there was no approval by an authorized user, and the payout transaction was not recorded in the Audit Log. | AG27: Failed result requires rework: The payout was released successfully, but there was no approval by an authorized user, and the payout transaction was not recorded in the Audit Log. | AH27: Fix Doctors & Commission workflow for "Payout approval" so actual behavior matches expected result: Only authorized staff can approve and the action is auditable. | AJ27: Defect SS
A28: BUG-027 | B28: DL2046 | C28: L2-046 | D28: Level 2 | E28: Doctors & Commission | G28: Doctor delete protection | H28: Functional | I28: Admin | J28: Medium | K28: No | L28: Failed | M28: Functional Bug | N28: Medium | O28: Open | P28: Unassigned | R28: 46268 | U28: Not Required | V28: Open | W28: =IF(R28="","",TODAY()-R28) -> 15 | X28: UAT | AA28: Abinesh | AB28: Required master data and user exist. | AC28: Use dedicated non-production test data. | AD28: 1. Sign in as Admin. 2. Try to delete a doctor with referrals. 3. Save or submit. 4. Refresh or reopen the record. 5. Compare the result with the pass condition. | AE28: Deletion is blocked or safely archived. | AF28: The system allows the doctor to be deleted even though the doctor has existing referral records.The deletion action is also not recorded in the Audit Log. | AG28: Failed result requires rework: The system allows the doctor to be deleted even though the doctor has existing referral records.The deletion action is also not recorded in the Audit Log. | AH28: Fix Doctors & Commission workflow for "Doctor delete protection" so actual behavior matches expected result: Deletion is blocked or safely archived. | AJ28: Defect SS
A29: BUG-028 | B29: DL2052 | C29: L2-052 | D29: Level 2 | E29: Test Master | G29: Package invalid member | H29: Functional | I29: Lab Manager | J29: Medium | K29: No | L29: Failed | M29: Functional Bug | N29: Medium | O29: Open | P29: Unassigned | R29: 46268 | U29: Not Required | V29: Open | W29: =IF(R29="","",TODAY()-R29) -> 15 | X29: QA | AA29: Rishidharshini | AB29: Required master data and user exist. | AC29: Use dedicated non-production test data. | AD29: 1. Sign in as Lab Manager. 2. Add inactive/duplicate tests to a package. 3. Save or submit. 4. Refresh or reopen the record. 5. Compare the result with the pass condition. | AE29: Invalid package setup is blocked. | AF29: Able to add an inactive test to the package | AG29: Failed result requires rework: Able to add an inactive test to the package | AH29: Fix Test Master workflow for "Package invalid member" so actual behavior matches expected result: Invalid package setup is blocked. | AJ29: Defect SS
A30: BUG-029 | B30: DL2054 | C30: L2-054 | D30: Level 2 | E30: Test Master | G30: Deactivate test | H30: Functional | I30: Lab Manager | J30: Medium | K30: No | L30: Failed | M30: Functional Bug | N30: Medium | O30: Open | P30: Unassigned | R30: 46268 | U30: Not Required | V30: Open | W30: =IF(R30="","",TODAY()-R30) -> 15 | X30: QA | AA30: Rishidharshini | AB30: Required master data and user exist. | AC30: Use dedicated non-production test data. | AD30: 1. Sign in as Lab Manager. 2. Deactivate a test after old bills exist. 3. Save or submit. 4. Refresh or reopen the record. 5. Compare the result with the pass condition. | AE30: Old snapshots remain; new billing cannot select it. | AF30: It is coming in the New billing even it is inactive | AG30: Billing/accounts workflow issue: financial transaction or document flow needs developer rework. | AH30: Fix Test Master workflow for "Deactivate test" so actual behavior matches expected result: Old snapshots remain; new billing cannot select it. | AJ30: Defect SS
A31: BUG-030 | B31: DL2056 | C31: L2-056 | D31: Level 2 | E31: Test Master | G31: Age-specific ranges | H31: Functional | I31: Lab Manager | J31: Medium | K31: No | L31: Failed | M31: Functional Bug | N31: Medium | O31: Open | P31: Unassigned | R31: 46268 | U31: Not Required | V31: Open | W31: =IF(R31="","",TODAY()-R31) -> 15 | X31: QA | AA31: Rishidharshini | AB31: Required master data and user exist. | AC31: Use dedicated non-production test data. | AD31: 1. Sign in as Lab Manager. 2. Configure/test age-dependent references. 3. Save or submit. 4. Refresh or reopen the record. 5. Compare the result with the pass condition. | AE31: Results use the correct range or the gap is recorded. | AF31: There is no test age | AG31: Failed result requires rework: There is no test age | AH31: Fix Test Master workflow for "Age-specific ranges" so actual behavior matches expected result: Results use the correct range or the gap is recorded. | AJ31: Defect SS
A32: BUG-031 | B32: DL2062 | C32: L2-062 | D32: Level 2 | E32: Billing & Payments | G32: Discount limit | H32: Functional | I32: Billing Cashier | J32: Medium | K32: No | L32: Failed | M32: Functional Bug | N32: Medium | O32: Open | P32: Unassigned | U32: Not Required | V32: Open | W32: =IF(R32="","",TODAY()-R32) | X32: UAT | AA32: Stephen | AB32: Required master data and user exist. | AC32: Use dedicated non-production test data. | AD32: 1. Sign in as Billing Cashier. 2. Apply an excessive or unauthorized discount. 3. Save or submit. 4. Refresh or reopen the record. 5. Compare the result with the pass condition. | AE32: Action is blocked and audited. | AF32: The discount amount is not restricted. | AG32: Billing/accounts workflow issue: financial transaction or document flow needs developer rework. | AH32: Fix Billing & Payments workflow for "Discount limit" so actual behavior matches expected result: Action is blocked and audited.
A33: BUG-032 | B33: DL2067 | C33: L2-067 | D33: Level 2 | E33: Billing & Payments | G33: Multiple modes | H33: Functional | I33: Billing Cashier | J33: Medium | K33: No | L33: Failed | M33: Functional Bug | N33: Medium | O33: Open | P33: Unassigned | U33: Not Required | V33: Open | W33: =IF(R33="","",TODAY()-R33) | X33: UAT | AA33: Stephen | AB33: Required master data and user exist. | AC33: Use dedicated non-production test data. | AD33: 1. Sign in as Billing Cashier. 2. Pay using cash, card, UPI, cheque and corporate credit. 3. Save or submit. 4. Refresh or reopen the record. 5. Compare the result with the pass condition. | AE33: Mode breakdown and history are correct. | AF33: Payment details can't work. | AG33: Billing/accounts workflow issue: financial transaction or document flow needs developer rework. | AH33: Fix Billing & Payments workflow for "Multiple modes" so actual behavior matches expected result: Mode breakdown and history are correct.
A34: BUG-033 | B34: DL2070 | C34: L2-070 | D34: Level 2 | E34: Billing & Payments | G34: Cancellation reason | H34: Functional | I34: Billing Cashier | J34: Medium | K34: No | L34: Failed | M34: Functional Bug | N34: Medium | O34: Open | P34: Unassigned | U34: Not Required | V34: Open | W34: =IF(R34="","",TODAY()-R34) | X34: UAT | AA34: Stephen | AB34: Required master data and user exist. | AC34: Use dedicated non-production test data. | AD34: 1. Sign in as Billing Cashier. 2. Cancel a bill without and with a reason. 3. Save or submit. 4. Refresh or reopen the record. 5. Compare the result with the pass condition. | AE34: Reason is required and downstream behavior follows policy. | AF34: The cancel reason field can't be shown. | AG34: Validation/UI rule issue: field constraints or required-field behavior do not match expected workflow. | AH34: Fix Billing & Payments workflow for "Cancellation reason" so actual behavior matches expected result: Reason is required and downstream behavior follows policy.
A35: BUG-034 | B35: DL2071 | C35: L2-071 | D35: Level 2 | E35: Billing & Payments | G35: Refund | H35: Functional | I35: Billing Cashier | J35: Critical | K35: Yes | L35: Failed | M35: Functional Bug | N35: Medium | O35: Open | P35: Unassigned | U35: Not Required | V35: Open | W35: =IF(R35="","",TODAY()-R35) | X35: UAT | AA35: Stephen | AB35: Required master data and user exist. | AC35: Use dedicated non-production test data. | AD35: 1. Sign in as Billing Cashier. 2. Refund a paid/cancelled bill. 3. Save or submit. 4. Refresh or reopen the record. 5. Compare the result with the pass condition. | AE35: Authorized refund reverses amounts and records history. | AF35: The revert reason has options. But the revert reason is important. So please ensure the revert reason is required. | AG35: Validation/UI rule issue: field constraints or required-field behavior do not match expected workflow. | AH35: Fix Billing & Payments workflow for "Refund" so actual behavior matches expected result: Authorized refund reverses amounts and records history.
A36: BUG-035 | B36: DL2073 | C36: L2-073 | D36: Level 2 | E36: Billing & Payments | G36: Corporate credit | H36: Functional | I36: Billing Cashier | J36: Medium | K36: No | L36: Failed | M36: Functional Bug | N36: Medium | O36: Open | P36: Unassigned | U36: Not Required | V36: Open | W36: =IF(R36="","",TODAY()-R36) | X36: UAT | AA36: Stephen | AB36: Required master data and user exist. | AC36: Use dedicated non-production test data. | AD36: 1. Sign in as Billing Cashier. 2. Bill an active corporate account. 3. Save or submit. 4. Refresh or reopen the record. 5. Compare the result with the pass condition. | AE36: Receivable and statement are correct. | AF36: Unable to settle bill using corporate credit. | AG36: Billing/accounts workflow issue: financial transaction or document flow needs developer rework. | AH36: Fix Billing & Payments workflow for "Corporate credit" so actual behavior matches expected result: Receivable and statement are correct.
A37: BUG-036 | B37: DL2074 | C37: L2-074 | D37: Level 2 | E37: Billing & Payments | G37: Credit limit | H37: Functional | I37: Billing Cashier | J37: Medium | K37: No | L37: Failed | M37: Functional Bug | N37: Medium | O37: Open | P37: Unassigned | U37: Not Required | V37: Open | W37: =IF(R37="","",TODAY()-R37) | X37: UAT | AA37: Stephen | AB37: Required master data and user exist. | AC37: Use dedicated non-production test data. | AD37: 1. Sign in as Billing Cashier. 2. Exceed corporate credit limit. 3. Save or submit. 4. Refresh or reopen the record. 5. Compare the result with the pass condition. | AE37: Warning/block follows policy. | AF37: Unable to settle bill using corporate credit. | AG37: Billing/accounts workflow issue: financial transaction or document flow needs developer rework. | AH37: Fix Billing & Payments workflow for "Credit limit" so actual behavior matches expected result: Warning/block follows policy.
A38: BUG-037 | B38: DL2077 | C38: L2-077 | D38: Level 2 | E38: Samples | G38: Automatic sample creation | H38: Functional | I38: Phlebotomist | J38: Medium | K38: No | L38: Failed | M38: Functional Bug | N38: Medium | O38: Open | P38: Unassigned | U38: Not Required | V38: Open | W38: =IF(R38="","",TODAY()-R38) | X38: QA | AA38: Stephen | AB38: Required master data and user exist. | AC38: Use dedicated non-production test data. | AD38: 1. Sign in as Phlebotomist. 2. Create a multi-test bill. 3. Save or submit. 4. Refresh or reopen the record. 5. Compare the result with the pass condition. | AE38: Correct samples/investigations are linked. | AF38: Can't create an appropriate role. | AG38: Access/RBAC setup issue: required role or permission does not allow the testcase workflow to complete. | AH38: Fix Samples workflow for "Automatic sample creation" so actual behavior matches expected result: Correct samples/investigations are linked.
A39: BUG-038 | B39: DL2078 | C39: L2-078 | D39: Level 2 | E39: Samples | G39: Unique sample ID | H39: Functional | I39: Phlebotomist | J39: Medium | K39: No | L39: Failed | M39: Functional Bug | N39: Medium | O39: Open | P39: Unassigned | U39: Not Required | V39: Open | W39: =IF(R39="","",TODAY()-R39) | X39: QA | AA39: Stephen | AB39: Required master data and user exist. | AC39: Use dedicated non-production test data. | AD39: 1. Sign in as Phlebotomist. 2. Create many samples concurrently. 3. Save or submit. 4. Refresh or reopen the record. 5. Compare the result with the pass condition. | AE39: Every sample ID and barcode is unique. | AF39: Can't create an appropriate role. | AG39: Access/RBAC setup issue: required role or permission does not allow the testcase workflow to complete. | AH39: Fix Samples workflow for "Unique sample ID" so actual behavior matches expected result: Every sample ID and barcode is unique.
A40: BUG-039 | B40: DL2079 | C40: L2-079 | D40: Level 2 | E40: Samples | G40: Collection time validation | H40: Functional | I40: Phlebotomist | J40: Medium | K40: No | L40: Failed | M40: Functional Bug | N40: Medium | O40: Open | P40: Unassigned | U40: Not Required | V40: Open | W40: =IF(R40="","",TODAY()-R40) | X40: QA | AA40: Stephen | AB40: Required master data and user exist. | AC40: Use dedicated non-production test data. | AD40: 1. Sign in as Phlebotomist. 2. Enter future or pre-DOB collection time. 3. Save or submit. 4. Refresh or reopen the record. 5. Compare the result with the pass condition. | AE40: Invalid time is blocked. | AF40: Can't create an appropriate role. | AG40: Access/RBAC setup issue: required role or permission does not allow the testcase workflow to complete. | AH40: Fix Samples workflow for "Collection time validation" so actual behavior matches expected result: Invalid time is blocked.
...

Sheet Developer Rework Summary
A1: Metric | B1: Formula / Value
A2: Total Bugs | B2: =COUNTA('Bug Tracker - 85'!A2:A200) -> 85
A3: Failed Bugs | B3: =COUNTIF('Bug Tracker - 85'!L:L,"Failed") -> 75
A4: N/A Review Bugs | B4: =COUNTIF('Bug Tracker - 85'!L:L,"N/A") -> 10
A5: Open Developer Items | B5: =COUNTIF('Bug Tracker - 85'!O:O,"Open") -> 75
A6: In Progress | B6: =COUNTIF('Bug Tracker - 85'!O:O,"In Progress") -> 0
A7: Fixed | B7: =COUNTIF('Bug Tracker - 85'!O:O,"Fixed") -> 0
A8: Closed | B8: =COUNTIF('Bug Tracker - 85'!V:V,"Closed") -> 0
A9: Unassigned | B9: =COUNTIF('Bug Tracker - 85'!P:P,"Unassigned") -> 83
A10: Critical | B10: =COUNTIF('Bug Tracker - 85'!N:N,"Critical") -> 0
A11: High | B11: =COUNTIF('Bug Tracker - 85'!N:N,"High") -> 20
A12: Medium | B12: =COUNTIF('Bug Tracker - 85'!N:N,"Medium") -> 52
A13: Low | B13: =COUNTIF('Bug Tracker - 85'!N:N,"Low") -> 13
A14: Release Rule | B14: All BUG-001 to BUG-085 must be Closed or formally Deferred before release.

Sheet Module Wise Bugs
A1: Module | B1: Total Bugs | C1: Failed | D1: N/A | E1: Critical | F1: High | G1: Medium | H1: Low | I1: Open/In Progress
A2: Accounts, Corporate & Expenses | B2: =COUNTIF('Bug Tracker - 85'!E:E,A2) -> 10 | C2: =COUNTIFS('Bug Tracker - 85'!E:E,A2,'Bug Tracker - 85'!L:L,"Failed") -> 7 | D2: =COUNTIFS('Bug Tracker - 85'!E:E,A2,'Bug Tracker - 85'!L:L,"N/A") -> 3 | E2: =COUNTIFS('Bug Tracker - 85'!E:E,A2,'Bug Tracker - 85'!N:N,"Critical") -> 0 | F2: =COUNTIFS('Bug Tracker - 85'!E:E,A2,'Bug Tracker - 85'!N:N,"High") -> 1 | G2: =COUNTIFS('Bug Tracker - 85'!E:E,A2,'Bug Tracker - 85'!N:N,"Medium") -> 6 | H2: =COUNTIFS('Bug Tracker - 85'!E:E,A2,'Bug Tracker - 85'!N:N,"Low") -> 3 | I2: =COUNTIFS('Bug Tracker - 85'!E:E,A2,'Bug Tracker - 85'!O:O,"Open")+COUNTIFS('Bug Tracker - 85'!E:E,A2,'Bug Tracker - 85'!O:O,"In Progress") -> 7
A3: Authentication & Session | B3: =COUNTIF('Bug Tracker - 85'!E:E,A3) -> 2 | C3: =COUNTIFS('Bug Tracker - 85'!E:E,A3,'Bug Tracker - 85'!L:L,"Failed") -> 2 | D3: =COUNTIFS('Bug Tracker - 85'!E:E,A3,'Bug Tracker - 85'!L:L,"N/A") -> 0 | E3: =COUNTIFS('Bug Tracker - 85'!E:E,A3,'Bug Tracker - 85'!N:N,"Critical") -> 0 | F3: =COUNTIFS('Bug Tracker - 85'!E:E,A3,'Bug Tracker - 85'!N:N,"High") -> 1 | G3: =COUNTIFS('Bug Tracker - 85'!E:E,A3,'Bug Tracker - 85'!N:N,"Medium") -> 1 | H3: =COUNTIFS('Bug Tracker - 85'!E:E,A3,'Bug Tracker - 85'!N:N,"Low") -> 0 | I3: =COUNTIFS('Bug Tracker - 85'!E:E,A3,'Bug Tracker - 85'!O:O,"Open")+COUNTIFS('Bug Tracker - 85'!E:E,A3,'Bug Tracker - 85'!O:O,"In Progress") -> 2
A4: Billing | B4: =COUNTIF('Bug Tracker - 85'!E:E,A4) -> 1 | C4: =COUNTIFS('Bug Tracker - 85'!E:E,A4,'Bug Tracker - 85'!L:L,"Failed") -> 1 | D4: =COUNTIFS('Bug Tracker - 85'!E:E,A4,'Bug Tracker - 85'!L:L,"N/A") -> 0 | E4: =COUNTIFS('Bug Tracker - 85'!E:E,A4,'Bug Tracker - 85'!N:N,"Critical") -> 0 | F4: =COUNTIFS('Bug Tracker - 85'!E:E,A4,'Bug Tracker - 85'!N:N,"High") -> 0 | G4: =COUNTIFS('Bug Tracker - 85'!E:E,A4,'Bug Tracker - 85'!N:N,"Medium") -> 1 | H4: =COUNTIFS('Bug Tracker - 85'!E:E,A4,'Bug Tracker - 85'!N:N,"Low") -> 0 | I4: =COUNTIFS('Bug Tracker - 85'!E:E,A4,'Bug Tracker - 85'!O:O,"Open")+COUNTIFS('Bug Tracker - 85'!E:E,A4,'Bug Tracker - 85'!O:O,"In Progress") -> 1
A5: Billing & Payments | B5: =COUNTIF('Bug Tracker - 85'!E:E,A5) -> 6 | C5: =COUNTIFS('Bug Tracker - 85'!E:E,A5,'Bug Tracker - 85'!L:L,"Failed") -> 6 | D5: =COUNTIFS('Bug Tracker - 85'!E:E,A5,'Bug Tracker - 85'!L:L,"N/A") -> 0 | E5: =COUNTIFS('Bug Tracker - 85'!E:E,A5,'Bug Tracker - 85'!N:N,"Critical") -> 0 | F5: =COUNTIFS('Bug Tracker - 85'!E:E,A5,'Bug Tracker - 85'!N:N,"High") -> 0 | G5: =COUNTIFS('Bug Tracker - 85'!E:E,A5,'Bug Tracker - 85'!N:N,"Medium") -> 6 | H5: =COUNTIFS('Bug Tracker - 85'!E:E,A5,'Bug Tracker - 85'!N:N,"Low") -> 0 | I5: =COUNTIFS('Bug Tracker - 85'!E:E,A5,'Bug Tracker - 85'!O:O,"Open")+COUNTIFS('Bug Tracker - 85'!E:E,A5,'Bug Tracker - 85'!O:O,"In Progress") -> 6
A6: Dashboard, Search, Notifications & Analytics | B6: =COUNTIF('Bug Tracker - 85'!E:E,A6) -> 2 | C6: =COUNTIFS('Bug Tracker - 85'!E:E,A6,'Bug Tracker - 85'!L:L,"Failed") -> 2 | D6: =COUNTIFS('Bug Tracker - 85'!E:E,A6,'Bug Tracker - 85'!L:L,"N/A") -> 0 | E6: =COUNTIFS('Bug Tracker - 85'!E:E,A6,'Bug Tracker - 85'!N:N,"Critical") -> 0 | F6: =COUNTIFS('Bug Tracker - 85'!E:E,A6,'Bug Tracker - 85'!N:N,"High") -> 0 | G6: =COUNTIFS('Bug Tracker - 85'!E:E,A6,'Bug Tracker - 85'!N:N,"Medium") -> 2 | H6: =COUNTIFS('Bug Tracker - 85'!E:E,A6,'Bug Tracker - 85'!N:N,"Low") -> 0 | I6: =COUNTIFS('Bug Tracker - 85'!E:E,A6,'Bug Tracker - 85'!O:O,"Open")+COUNTIFS('Bug Tracker - 85'!E:E,A6,'Bug Tracker - 85'!O:O,"In Progress") -> 2
A7: Developer, Subscription & Tenant | B7: =COUNTIF('Bug Tracker - 85'!E:E,A7) -> 2 | C7: =COUNTIFS('Bug Tracker - 85'!E:E,A7,'Bug Tracker - 85'!L:L,"Failed") -> 2 | D7: =COUNTIFS('Bug Tracker - 85'!E:E,A7,'Bug Tracker - 85'!L:L,"N/A") -> 0 | E7: =COUNTIFS('Bug Tracker - 85'!E:E,A7,'Bug Tracker - 85'!N:N,"Critical") -> 0 | F7: =COUNTIFS('Bug Tracker - 85'!E:E,A7,'Bug Tracker - 85'!N:N,"High") -> 2 | G7: =COUNTIFS('Bug Tracker - 85'!E:E,A7,'Bug Tracker - 85'!N:N,"Medium") -> 0 | H7: =COUNTIFS('Bug Tracker - 85'!E:E,A7,'Bug Tracker - 85'!N:N,"Low") -> 0 | I7: =COUNTIFS('Bug Tracker - 85'!E:E,A7,'Bug Tracker - 85'!O:O,"Open")+COUNTIFS('Bug Tracker - 85'!E:E,A7,'Bug Tracker - 85'!O:O,"In Progress") -> 2
A8: Doctor & Patient Portals | B8: =COUNTIF('Bug Tracker - 85'!E:E,A8) -> 3 | C8: =COUNTIFS('Bug Tracker - 85'!E:E,A8,'Bug Tracker - 85'!L:L,"Failed") -> 3 | D8: =COUNTIFS('Bug Tracker - 85'!E:E,A8,'Bug Tracker - 85'!L:L,"N/A") -> 0 | E8: =COUNTIFS('Bug Tracker - 85'!E:E,A8,'Bug Tracker - 85'!N:N,"Critical") -> 0 | F8: =COUNTIFS('Bug Tracker - 85'!E:E,A8,'Bug Tracker - 85'!N:N,"High") -> 2 | G8: =COUNTIFS('Bug Tracker - 85'!E:E,A8,'Bug Tracker - 85'!N:N,"Medium") -> 1 | H8: =COUNTIFS('Bug Tracker - 85'!E:E,A8,'Bug Tracker - 85'!N:N,"Low") -> 0 | I8: =COUNTIFS('Bug Tracker - 85'!E:E,A8,'Bug Tracker - 85'!O:O,"Open")+COUNTIFS('Bug Tracker - 85'!E:E,A8,'Bug Tracker - 85'!O:O,"In Progress") -> 3
A9: Doctor Portal | B9: =COUNTIF('Bug Tracker - 85'!E:E,A9) -> 1 | C9: =COUNTIFS('Bug Tracker - 85'!E:E,A9,'Bug Tracker - 85'!L:L,"Failed") -> 1 | D9: =COUNTIFS('Bug Tracker - 85'!E:E,A9,'Bug Tracker - 85'!L:L,"N/A") -> 0 | E9: =COUNTIFS('Bug Tracker - 85'!E:E,A9,'Bug Tracker - 85'!N:N,"Critical") -> 0 | F9: =COUNTIFS('Bug Tracker - 85'!E:E,A9,'Bug Tracker - 85'!N:N,"High") -> 1 | G9: =COUNTIFS('Bug Tracker - 85'!E:E,A9,'Bug Tracker - 85'!N:N,"Medium") -> 0 | H9: =COUNTIFS('Bug Tracker - 85'!E:E,A9,'Bug Tracker - 85'!N:N,"Low") -> 0 | I9: =COUNTIFS('Bug Tracker - 85'!E:E,A9,'Bug Tracker - 85'!O:O,"Open")+COUNTIFS('Bug Tracker - 85'!E:E,A9,'Bug Tracker - 85'!O:O,"In Progress") -> 1
A10: Doctors & Commission | B10: =COUNTIF('Bug Tracker - 85'!E:E,A10) -> 6 | C10: =COUNTIFS('Bug Tracker - 85'!E:E,A10,'Bug Tracker - 85'!L:L,"Failed") -> 5 | D10: =COUNTIFS('Bug Tracker - 85'!E:E,A10,'Bug Tracker - 85'!L:L,"N/A") -> 1 | E10: =COUNTIFS('Bug Tracker - 85'!E:E,A10,'Bug Tracker - 85'!N:N,"Critical") -> 0 | F10: =COUNTIFS('Bug Tracker - 85'!E:E,A10,'Bug Tracker - 85'!N:N,"High") -> 2 | G10: =COUNTIFS('Bug Tracker - 85'!E:E,A10,'Bug Tracker - 85'!N:N,"Medium") -> 2 | H10: =COUNTIFS('Bug Tracker - 85'!E:E,A10,'Bug Tracker - 85'!N:N,"Low") -> 2 | I10: =COUNTIFS('Bug Tracker - 85'!E:E,A10,'Bug Tracker - 85'!O:O,"Open")+COUNTIFS('Bug Tracker - 85'!E:E,A10,'Bug Tracker - 85'!O:O,"In Progress") -> 5
A11: Inventory | B11: =COUNTIF('Bug Tracker - 85'!E:E,A11) -> 11 | C11: =COUNTIFS('Bug Tracker - 85'!E:E,A11,'Bug Tracker - 85'!L:L,"Failed") -> 7 | D11: =COUNTIFS('Bug Tracker - 85'!E:E,A11,'Bug Tracker - 85'!L:L,"N/A") -> 4 | E11: =COUNTIFS('Bug Tracker - 85'!E:E,A11,'Bug Tracker - 85'!N:N,"Critical") -> 0 | F11: =COUNTIFS('Bug Tracker - 85'!E:E,A11,'Bug Tracker - 85'!N:N,"High") -> 4 | G11: =COUNTIFS('Bug Tracker - 85'!E:E,A11,'Bug Tracker - 85'!N:N,"Medium") -> 1 | H11: =COUNTIFS('Bug Tracker - 85'!E:E,A11,'Bug Tracker - 85'!N:N,"Low") -> 6 | I11: =COUNTIFS('Bug Tracker - 85'!E:E,A11,'Bug Tracker - 85'!O:O,"Open")+COUNTIFS('Bug Tracker - 85'!E:E,A11,'Bug Tracker - 85'!O:O,"In Progress") -> 7
A12: Notifications | B12: =COUNTIF('Bug Tracker - 85'!E:E,A12) -> 1 | C12: =COUNTIFS('Bug Tracker - 85'!E:E,A12,'Bug Tracker - 85'!L:L,"Failed") -> 1 | D12: =COUNTIFS('Bug Tracker - 85'!E:E,A12,'Bug Tracker - 85'!L:L,"N/A") -> 0 | E12: =COUNTIFS('Bug Tracker - 85'!E:E,A12,'Bug Tracker - 85'!N:N,"Critical") -> 0 | F12: =COUNTIFS('Bug Tracker - 85'!E:E,A12,'Bug Tracker - 85'!N:N,"High") -> 1 | G12: =COUNTIFS('Bug Tracker - 85'!E:E,A12,'Bug Tracker - 85'!N:N,"Medium") -> 0 | H12: =COUNTIFS('Bug Tracker - 85'!E:E,A12,'Bug Tracker - 85'!N:N,"Low") -> 0 | I12: =COUNTIFS('Bug Tracker - 85'!E:E,A12,'Bug Tracker - 85'!O:O,"Open")+COUNTIFS('Bug Tracker - 85'!E:E,A12,'Bug Tracker - 85'!O:O,"In Progress") -> 1
A13: Patients & Visits | B13: =COUNTIF('Bug Tracker - 85'!E:E,A13) -> 3 | C13: =COUNTIFS('Bug Tracker - 85'!E:E,A13,'Bug Tracker - 85'!L:L,"Failed") -> 3 | D13: =COUNTIFS('Bug Tracker - 85'!E:E,A13,'Bug Tracker - 85'!L:L,"N/A") -> 0 | E13: =COUNTIFS('Bug Tracker - 85'!E:E,A13,'Bug Tracker - 85'!N:N,"Critical") -> 0 | F13: =COUNTIFS('Bug Tracker - 85'!E:E,A13,'Bug Tracker - 85'!N:N,"High") -> 0 | G13: =COUNTIFS('Bug Tracker - 85'!E:E,A13,'Bug Tracker - 85'!N:N,"Medium") -> 3 | H13: =COUNTIFS('Bug Tracker - 85'!E:E,A13,'Bug Tracker - 85'!N:N,"Low") -> 0 | I13: =COUNTIFS('Bug Tracker - 85'!E:E,A13,'Bug Tracker - 85'!O:O,"Open")+COUNTIFS('Bug Tracker - 85'!E:E,A13,'Bug Tracker - 85'!O:O,"In Progress") -> 3
... A18: Test Master | B18: =COUNTIF('Bug Tracker - 85'!E:E,A18) -> 3 | C18: =COUNTIFS('Bug Tracker - 85'!E:E,A18,'Bug Tracker - 85'!L:L,"Failed") -> 3 | D18: =COUNTIFS('Bug Tracker - 85'!E:E,A18,'Bug Tracker - 85'!L:L,"N/A") -> 0 | E18: =COUNTIFS('Bug Tracker - 85'!E:E,A18,'Bug Tracker - 85'!N:N,"Critical") -> 0 | F18: =COUNTIFS('Bug Tracker - 85'!E:E,A18,'Bug Tracker - 85'!N:N,"High") -> 0 | G18: =COUNTIFS('Bug Tracker - 85'!E:E,A18,'Bug Tracker - 85'!N:N,"Medium") -> 3 | H18: =COUNTIFS('Bug Tracker - 85'!E:E,A18,'Bug Tracker - 85'!N:N,"Low") -> 0 | I18: =COUNTIFS('Bug Tracker - 85'!E:E,A18,'Bug Tracker - 85'!O:O,"Open")+COUNTIFS('Bug Tracker - 85'!E:E,A18,'Bug Tracker - 85'!O:O,"In Progress") -> 3

Sheet Lookup
A1: Developer Bug Rework Maintenance Rule | B1: Details
A2: Step 1 | B2: Assign Developer Name for every Unassigned bug.
A3: Step 2 | B3: Developer fills Developer Rework Date, Reason / Root Cause, Fix Notes, and Fix Build.
A4: Step 3 | B4: QA retests only after Bug Status is Fixed.
A5: Step 4 | B5: Failed retest becomes Reopened; Passed retest becomes Closed.
A6: Step 5 | B6: N/A items need Product/QA approval with written reason before closure/deferment.
A7: Release Gate | B7: No release until all 85 items are Closed or formally Deferred.
A8: Source Workbook | B8: C:\Users\rishi\Downloads\LIMS_Three_Level_Release_Testing_Tracker (1) (2) (1).xlsx
